<?xml version="1.0" encoding="utf-8"?>
<!-- This URDF was automatically created by SolidWorks to URDF Exporter! Originally created by Stephen Brawner (brawner@gmail.com) 
     Commit Version: 1.6.0-4-g7f85cfe  Build Version: 1.6.7995.38578
     For more information, please see http://wiki.ros.org/sw_urdf_exporter -->
<robot
  name="arm">
  <link
    name="base_link">
    <inertial>
      <origin
        xyz="5.13312732192816E-24 2.98225536792769E-18 0.012"
        rpy="0 0 0" />
      <mass
        value="0.023090706003885" />
      <inertia
        ixx="2.87623606660892E-06"
        ixy="1.41059322098675E-37"
        ixz="2.82120223810858E-28"
        iyy="2.87623606660893E-06"
        iyz="1.14794370197489E-38"
        izz="3.53576435684489E-06" />
    </inertial>
    <visual>
      <origin
        xyz="0 0 0"
        rpy="0 0 0" />
      <geometry>
        <mesh
          filename="package://arm/meshes/base_link.STL" />
      </geometry>
      <material
        name="">
        <color
          rgba="0.627450980392157 0.627450980392157 0.627450980392157 1" />
      </material>
    </visual>
    <collision>
      <origin
        xyz="0 0 0"
        rpy="0 0 0" />
      <geometry>
        <mesh
          filename="package://arm/meshes/base_link.STL" />
      </geometry>
    </collision>
  </link>
  <link
    name="link1">
    <inertial>
      <origin
        xyz="-0.0027816844022008 0.00338125927703351 0.008"
        rpy="0 0 0" />
      <mass
        value="0.000988216541243044" />
      <inertia
        ixx="1.90823126970333E-08"
        ixy="1.38506359525948E-10"
        ixz="8.19156806945474E-25"
        iyy="1.45517296276645E-08"
        iyz="3.18460387833784E-25"
        izz="2.78202342494956E-08" />
    </inertial>
    <visual>
      <origin
        xyz="0 0 0"
        rpy="0 0 0" />
      <geometry>
        <mesh
          filename="package://arm/meshes/link1.STL" />
      </geometry>
      <material
        name="">
        <color
          rgba="0.627450980392157 0.627450980392157 0.627450980392157 1" />
      </material>
    </visual>
    <collision>
      <origin
        xyz="0 0 0"
        rpy="0 0 0" />
      <geometry>
        <mesh
          filename="package://arm/meshes/link1.STL" />
      </geometry>
    </collision>
  </link>
  <joint
    name="joint1"
    type="revolute">
    <origin
      xyz="0 0 0.024"
      rpy="0 0 1.5708" />
    <parent
      link="base_link" />
    <child
      link="link1" />
    <axis
      xyz="0 0 -1" />
    <limit
      lower="-3.14"
      upper="3.14"
      effort="10"
      velocity="3" />
  </joint>
  <link
    name="link2">
    <inertial>
      <origin
        xyz="-0.000877000214864543 0.0214121325210412 -0.00397779628631471"
        rpy="0 0 0" />
      <mass
        value="0.00233780679878476" />
      <inertia
        ixx="1.8455216571155E-07"
        ixy="-1.05958317402517E-08"
        ixz="1.38506359525958E-10"
        iyy="4.82744767416521E-08"
        iyz="-8.75660568859961E-23"
        izz="1.97720411691857E-07" />
    </inertial>
    <visual>
      <origin
        xyz="0 0 0"
        rpy="0 0 0" />
      <geometry>
        <mesh
          filename="package://arm/meshes/link2.STL" />
      </geometry>
      <material
        name="">
        <color
          rgba="1 1 1 1" />
      </material>
    </visual>
    <collision>
      <origin
        xyz="0 0 0"
        rpy="0 0 0" />
      <geometry>
        <mesh
          filename="package://arm/meshes/link2.STL" />
      </geometry>
    </collision>
  </link>
  <joint
    name="joint2"
    type="revolute">
    <origin
      xyz="0 -0.0090485 0.008"
      rpy="1.5708 0 0" />
    <parent
      link="link1" />
    <child
      link="link2" />
    <axis
      xyz="0 0 -1" />
    <limit
      lower="-3.14"
      upper="3.14"
      effort="10"
      velocity="3" />
  </joint>
  <link
    name="link3">
    <inertial>
      <origin
        xyz="-0.00150341472148203 0.0143292563880445 -0.00316059563598266"
        rpy="0 0 0" />
      <mass
        value="0.0023031669438909" />
      <inertia
        ixx="1.32938896258025E-07"
        ixy="6.04181633782314E-09"
        ixz="-3.08851189449812E-09"
        iyy="7.20863623608677E-08"
        iyz="1.13982053665467E-08"
        izz="1.51665716979718E-07" />
    </inertial>
    <visual>
      <origin
        xyz="0 0 0"
        rpy="0 0 0" />
      <geometry>
        <mesh
          filename="package://arm/meshes/link3.STL" />
      </geometry>
      <material
        name="">
        <color
          rgba="1 1 1 1" />
      </material>
    </visual>
    <collision>
      <origin
        xyz="0 0 0"
        rpy="0 0 0" />
      <geometry>
        <mesh
          filename="package://arm/meshes/link3.STL" />
      </geometry>
    </collision>
  </link>
  <joint
    name="joint3"
    type="revolute">
    <origin
      xyz="0 0.030167 -0.01945"
      rpy="-3.1416 0 3.1416" />
    <parent
      link="link2" />
    <child
      link="link3" />
    <axis
      xyz="0 0 -1" />
    <limit
      lower="-3.14"
      upper="3.14"
      effort="10"
      velocity="3" />
  </joint>
  <link
    name="link4">
    <inertial>
      <origin
        xyz="0.000664457063794661 0.00321500697518318 -0.00125"
        rpy="0 0 0" />
      <mass
        value="0.00040369422160084" />
      <inertia
        ixx="1.11604754637072E-08"
        ixy="-1.69559702950831E-09"
        ixz="2.1307410154117E-25"
        iyy="3.30668406576112E-09"
        iyz="1.35689523965486E-24"
        izz="1.40466447153008E-08" />
    </inertial>
    <visual>
      <origin
        xyz="0 0 0"
        rpy="0 0 0" />
      <geometry>
        <mesh
          filename="package://arm/meshes/link4.STL" />
      </geometry>
      <material
        name="">
        <color
          rgba="1 1 1 1" />
      </material>
    </visual>
    <collision>
      <origin
        xyz="0 0 0"
        rpy="0 0 0" />
      <geometry>
        <mesh
          filename="package://arm/meshes/link4.STL" />
      </geometry>
    </collision>
  </link>
  <joint
    name="joint4"
    type="revolute">
    <origin
      xyz="0.002964 0.018445 0.006"
      rpy="0 0 0" />
    <parent
      link="link3" />
    <child
      link="link4" />
    <axis
      xyz="0 0 1" />
    <limit
      lower="-3.14"
      upper="3.14"
      effort="10"
      velocity="3" />
  </joint>
</robot>